2024-10-21 11:54:16,174 - ERROR - Error in data loading: [Errno 2] No such file or directory: 'data/syn_flood_train.csv'
2024-10-21 11:54:16,175 - ERROR - An error occurred: [Errno 2] No such file or directory: 'data/syn_flood_train.csv'
Traceback (most recent call last):
  File "strlim.py", line 460, in main
    train_df, test_df = data_module.load_and_preprocess_data(data_paths)
  File "strlim.py", line 60, in load_and_preprocess_data
    dfs = {name: pd.read_csv(path) for name, path in data_paths.items()}
  File "strlim.py", line 60, in <dictcomp>
    dfs = {name: pd.read_csv(path) for name, path in data_paths.items()}
  File "/home/surya/.local/lib/python3.8/site-packages/pandas/util/_decorators.py", line 311, in wrapper
    return func(*args, **kwargs)
  File "/home/surya/.local/lib/python3.8/site-packages/pandas/io/parsers/readers.py", line 678, in read_csv
    return _read(filepath_or_buffer, kwds)
  File "/home/surya/.local/lib/python3.8/site-packages/pandas/io/parsers/readers.py", line 575, in _read
    parser = TextFileReader(filepath_or_buffer, **kwds)
  File "/home/surya/.local/lib/python3.8/site-packages/pandas/io/parsers/readers.py", line 932, in __init__
    self._engine = self._make_engine(f, self.engine)
  File "/home/surya/.local/lib/python3.8/site-packages/pandas/io/parsers/readers.py", line 1216, in _make_engine
    self.handles = get_handle(  # type: ignore[call-overload]
  File "/home/surya/.local/lib/python3.8/site-packages/pandas/io/common.py", line 786, in get_handle
    handle = open(
FileNotFoundError: [Errno 2] No such file or directory: 'data/syn_flood_train.csv'
